Workbook

Sheet 0_Lisez-moi
B2: CHALLENGE MOBITAG 2026 - MODELE FINANCIER 24 MOIS
B3: Candidat : [RAISON SOCIALE] - Proposition « Mobitag Nouvelle Génération »
B4: Montants en francs CFP (XPF), hors taxes. Parité de référence : 1 EUR = 119,3317 XPF (parité fixe).
B6: OBJET
C7: Réponse à la section 6 du dossier candidats : projection 24 mois en F CFP distinguant chiffre d'affaires, coûts variables, coûts fixes, investissements, économies générées, fiscalité, reversements, résultat économique et besoin de financement, en trois scénarios.
B9: PERIMETRE DU COMPTE DE RESULTAT
C10: Le P&L modélisé est celui du SERVICE Mobitag Nouvelle Génération dans son ensemble, en vue OPT-NC. Ce choix est imposé par la formule d'équilibre du dossier, qui intègre les coûts évités : ces coûts sont ceux de l'OPT-NC. La répartition de la valeur entre l'OPT-NC, le candidat et les partenaires fait l'objet de l'onglet 9.
B12: PRINCIPE DIRECTEUR : AUCUNE REDONDANCE AVEC LE CATALOGUE HELIA
C13: Le SMS est déjà illimité pour la quasi-totalité des clients Helia : les quatre Forfaits M (2 Go à 100 Go, 1 000 à 10 000 F TTC/mois) incluent tous les SMS illimités, les Recharges Packagées également, et une option Pack SMS existe dès 318 F TTC. Toute monetisation fondée sur la vente de volume, de quota, de crédit ou de palier d'envoi au particulier serait donc redondante par construction.
C14: AUCUNE ligne de ce modèle ne repose sur la vente de SMS au particulier. Le socle d'envoi reste gratuit, sans plafond payant et sans option d'extension de volume. Voir la cartographie de non-redondance dans la note de candidature.
B16: LES CINQ SOURCES DE SOUTENABILITE RETENUES
B17: 1. TCO legacy évité (pilier) | C17: Arrêt du socle technique historique et de sa TMA. Contributeur principal à l'équilibre : démontrable, immédiat, et sans aucun risque de cannibalisation puisqu'il s'agit de charges internes et non d'une offre. Détail poste par poste dans l'onglet 2.
B18: 2. Coûts d'abus évités | C18: Le dispositif de confiance sur le canal 1000 (vérification d'origine, signalement en un clic, maîtrise par le destinataire) réduit mécaniquement le traitement manuel des réclamations et des abus côté OPT-NC. Ce poste porte son propre taux d'évitement dans l'onglet 2.
B19: 3. Apport d'affaires B2B vers Helia PRO | C19: Mise en œuvre monetisée de l'exigence F10 : les usages professionnels détectés sont orientés vers Helia PRO. Anti-cannibalisation par construction, puisque le service alimente l'offre professionnelle au lieu de la doubler. Valorisé en marge attribuée, avec un taux d'attribution volontairement prudent.
B20: 4. Apport d'affaires B2C - activation de lignes | C20: Mobitag est le seul point de contact de l'OPT-NC avec les personnes sans ligne active : téléphone perdu, volé, cassé, hors forfait, poste partagé d'une mairie ou d'une médiathèque. Cette audience est structurellement inaccessible au reste du catalogue Helia. Orientation clairement identifiée, jamais dissimulée, jamais insérée dans un message personnel.
B21: 5. Sponsoring consenti | C21: Partenariat identifié et accepté par l'utilisateur, hors du contenu des messages. Non redondant : l'OPT-NC ne commercialise pas d'espace publicitaire. Inventaire étroit, donc volontairement NUL en scénario prudent : le modèle ne dépend jamais de cette ligne.
B23: FORMULES IMPOSEES PAR LE DOSSIER (section 6)
B24: Marge contributive | C24: =chiffre d'affaires − coûts variables − reversements éventuels
B25: Equilibre économique 24 mois | C25: =marge contributive + coûts évités − coûts fixes − investissements − fiscalité applicable
C26: Ces deux formules sont appliquées littéralement dans les onglets 4 à 6, aux lignes « Marge contributive » et « Equilibre économique cumulé ».
B28: MODE D'EMPLOI
C29: Seules les cellules sur fond JAUNE sont saisissables. Toutes les autres sont calculées. Modifier une hypothèse dans l'onglet 1 met à jour les trois scénarios, le point mort, la synthèse et la sensibilité.
C30: Chaque hypothèse porte une source et un niveau de confiance. Les hypothèses marquées « A VALIDER OPT » sont celles dont la confirmation est demandée à l'OPT-NC : volumétrie réelle du service, coût complet actuel, et part des envois émanant d'utilisateurs sans ligne Helia active.
B32: SOMMAIRE
B33: 1_Hypotheses | C33: Hypothèses paramétrables en trois scénarios, avec source et niveau de confiance.
B34: 2_Couts_evites | C34: Coût complet annuel actuel du service, poste par poste, et taux d'évitement retenu.
B35: 3_Unit_economics | C35: Coûts unitaires, coût de revient d'un SMS gratuit, valeur d'un apport, ratios de contrôle.
B36: 4_PL_Prudent | C36: Compte de résultat mensuel sur 24 mois - scénario prudent.
B37: 5_PL_Central | C37: Compte de résultat mensuel sur 24 mois - scénario central.
B38: 6_PL_Ambitieux | C38: Compte de résultat mensuel sur 24 mois - scénario ambitieux.
B39: 7_Synthese | C39: Comparaison des trois scénarios : point mort, résultat cumulé, besoin de financement, graphiques.
B40: 8_Sensibilite | C40: Sensibilité du résultat 24 mois aux sept variables les plus structurantes.
B41: 9_Partage_valeur | C41: Répartition de la valeur entre OPT-NC, candidat et partenaires, par phase.

Sheet 1_Hypotheses
A1: HYPOTHESES - 3 SCENARIOS
A2: Cellules jaunes = saisie. Montants en XPF HT.
A3: Aucune hypothèse de vente de volume SMS au particulier : le SMS est déjà illimité dans les Forfaits M et les Recharges Packagées Helia.
A5: Hypothèse | B5: Unité | C5: Prudent | D5: Central | E5: Ambitieux | F5: Confiance | G5: Source / justification
A6: A. AUDIENCE ET VOLUMETRIE DU SERVICE
A7: Utilisateurs actifs mensuels (MAU) au mois 1 | B7: pers. | C7: 5000 | D7: 8000 | E7: 12000 | F7: A VALIDER OPT | G7: Volumétrie actuelle du service non publiée. Fourchette déduite de la population de Nouvelle-Calédonie (~268 000 hab.) et du parc mobile Mobilis/Liberté. Question posée à l'OPT-NC.
A8: Croissance mensuelle des MAU après refonte | B8: %/mois | C8: 0.015 | D8: 0.025 | E8: 0.035 | F8: Moyenne | G8: Effet refonte UX + accessibilité mobile et bas débit (F02, F08). Prudent = simple maintien de la tendance, ambitieux = relance par la notoriété du canal 1000.
A9: Plafond de saturation des MAU | B9: pers. | C9: 10000 | D9: 18000 | E9: 22000 | F9: Moyenne | G9: Borne haute réaliste au regard de la taille du marché calédonien. Empêche toute projection de croissance non bornée.
A10: SMS gratuits envoyés par MAU et par mois | B10: SMS | C10: 3 | D10: 3.5 | E10: 4 | F10: A VALIDER OPT | G10: Usage occasionnel par nature. Sert au calcul du coût d'acheminement, jamais à une facturation.
A11: B. APPORT D'AFFAIRES B2B VERS HELIA PRO (exigence F10 monetisée)
A12: Part des MAU détectés en usage professionnel | B12: %/mois | C12: 0.004 | D12: 0.007 | E12: 0.01 | F12: Moyenne | G12: Détection par faisceau d'indices (récurrence, signature commerciale, gabarit de message). Le dossier impose déjà cette distinction en F10.
A13: Taux de prise de contact vers Helia PRO | B13: % | C13: 0.25 | D13: 0.35 | E13: 0.45 | F13: Moyenne | G13: Orientation contextuelle au moment précis du besoin non satisfait : taux supérieur à une sollicitation publicitaire classique.
A14: Taux de conversion en client Helia PRO | B14: % | C14: 0.04 | D14: 0.06 | E14: 0.09 | F14: A VALIDER OPT | G14: Taux de transformation d'un lead entrant qualifié. A confronter au tunnel commercial réel d'Helia PRO.
A15: Marge annuelle moyenne d'un client Helia PRO | B15: XPF/an | C15: 90000 | D15: 130000 | E15: 190000 | F15: A VALIDER OPT | G15: MARGE et non chiffre d'affaires. Ordre de grandeur déduit du positionnement de la plateforme d'envoi en masse (60 000 F HT/mois, 10 000 SMS inclus) et des petits comptes.
A16: Taux d'attribution de la marge à Mobitag NG | B16: % | C16: 0.3 | D16: 0.4 | E16: 0.45 | F16: Moyenne | G16: Attribution volontairement partielle : l'effort commercial Helia PRO conserve la part majoritaire ou paritaire de la valeur. Evite toute surestimation.
A17: Attrition mensuelle des comptes PRO apportés | B17: %/mois | C17: 0.02 | D17: 0.013 | E17: 0.009 | F17: Moyenne | G17: Equivaut à une rétention annuelle de 78 % / 85 % / 90 %.
A18: Mois de démarrage de l'orientation PRO | B18: mois | C18: 10 | D18: 8 | E18: 7 | F18: Elevée | G18: Démarrage après bascule du service refondu et mise en place de la convention d'apport.
A19: C. APPORT D'AFFAIRES B2C - ACTIVATION DE LIGNES (audience sans ligne active)
A20: Part des MAU sans ligne Helia active ou hors forfait | B20: % | C20: 0.12 | D20: 0.18 | E20: 0.25 | F20: A VALIDER OPT | G20: C'est l'hypothèse la plus structurante du modèle et la question prioritaire posée à l'OPT-NC. Usages visés : mobile perdu, volé, cassé, déchargé, hors forfait, poste partagé (mairie, médiathèque), personne sans mobile.
A21: Taux de prise de contact vers une offre Helia identifiée | B21: %/mois | C21: 0.08 | D21: 0.12 | E21: 0.15 | F21: Moyenne | G21: Encart clairement identifié, jamais inséré dans un message personnel, jamais dissimulé. Conforme à la section 15 du dossier.
A22: Taux d'activation ou de souscription | B22: % | C22: 0.04 | D22: 0.06 | E22: 0.07 | F22: A VALIDER OPT | G22: Population en situation de besoin réel et immédiat de rétablir sa ligne.
A23: Marge annuelle moyenne d'une ligne grand public | B23: XPF/an | C23: 18000 | D23: 26000 | E23: 36000 | F23: A VALIDER OPT | G23: MARGE et non chiffre d'affaires. Ordre de grandeur déduit des Forfaits M (1 000 à 10 000 F TTC/mois) et du prépayé, pondéré vers le bas du catalogue.
A24: Taux d'attribution de la marge à Mobitag NG | B24: % | C24: 0.25 | D24: 0.35 | E24: 0.4 | F24: Moyenne | G24: Attribution minoritaire : la souscription reste portée par le réseau de distribution Helia.
A25: Attrition mensuelle des lignes apportées | B25: %/mois | C25: 0.024 | D25: 0.018 | E25: 0.013 | F25: Moyenne | G25: Equivaut à une rétention annuelle de 75 % / 80 % / 85 %.
A26: Mois de démarrage de l'orientation B2C | B26: mois | C26: 10 | D26: 8 | E26: 7 | F26: Elevée | G26: Post-bascule, après validation du parcours par le DPO et la direction marketing.
A27: D. SPONSORING CONSENTI (ligne d'appoint, nulle en scénario prudent)
A28: Revenu mensuel en régime établi | B28: XPF/mois | C28: 0 | D28: 120000 | E28: 280000 | F28: Moyenne | G28: Inventaire étroit sur un marché de 268 000 habitants. Nul en prudent : la soutenabilité du modèle ne dépend jamais de cette ligne.
A29: Mois de démarrage du sponsoring | B29: mois | C29: 25 | D29: 14 | E29: 11 | F29: Moyenne | G29: 25 = jamais activé sur l'horizon en scénario prudent.
A30: Durée de montée en charge | B30: mois | C30: 6 | D30: 6 | E30: 5 | F30: Moyenne | G30: Montée linéaire jusqu'au régime établi.
A31: Reversement régie / partenaire | B31: % du CA | C31: 0.15 | D31: 0.15 | E31: 0.15 | F31: Moyenne | G31: Commission d'une régie locale. Entre dans les « reversements éventuels » de la formule de marge contributive.
A32: E. COUTS VARIABLES
A33: Coût interne d'acheminement d'un SMS | B33: XPF/SMS | C33: 2.5 | D33: 2 | E33: 1.5 | F33: A VALIDER OPT | G33: Coût interne réseau, hors tarif commercial. Décroît avec la mutualisation de la passerelle.
A34: Coût d'infrastructure variable par MAU | B34: XPF/mois | C34: 4 | D34: 3 | E34: 2 | F34: Elevée | G34: Calculé sur tarifs publics de calcul, stockage et sortie réseau pour une charge conteneurisée sans état.
A35: F. COUTS FIXES DU SERVICE NOUVELLE GENERATION
A36: Run technique et produit | B36: ETP | C36: 0.28 | D36: 0.25 | E36: 0.2 | F36: Moyenne | G36: Exploitation d'une stack conteneurisée sans état, avec CI/CD, déploiements sans interruption et supervision automatisée. Ce run ne démarre qu'à la bascule : avant, la charge de construction est portée par l'investissement.
A37: Coût annuel chargé d'un ETP | B37: XPF/an | C37: 8500000 | D37: 8000000 | E37: 7500000 | F37: Elevée | G37: Coût chargé d'un profil technique confirmé en Nouvelle-Calédonie.
A38: Hébergement cloud | B38: XPF/mois | C38: 70000 | D38: 55000 | E38: 45000 | F38: Elevée | G38: Socle conteneurisé, base de données managée, sauvegardes, observabilité, environnements de test.
A39: Support et modération résiduels | B39: XPF/mois | C39: 30000 | D39: 22000 | E39: 16000 | F39: Moyenne | G39: Résiduel après automatisation de l'anti-abus et du signalement (F05, F11).
A40: Communication et notoriété | B40: XPF/mois | C40: 25000 | D40: 40000 | E40: 60000 | F40: Moyenne | G40: Poste nouveau, absent du service historique. Soutient la croissance des MAU.
A41: Environnements de dev, test et pré-production (avant bascule) | B41: XPF/mois | C41: 20000 | D41: 25000 | E41: 30000 | F41: Elevée | G41: Seul coût fixe courant avant la bascule. La charge de construction est portée par l'investissement, jamais par le run : le modèle ne compte pas deux fois la même équipe.
...

Sheet 2_Couts_evites
A1: COUT COMPLET ACTUEL DU SERVICE ET TAUX D'EVITEMENT
A2: Le coût évité est le contributeur principal à l'équilibre. Il porte sur des charges internes OPT-NC : aucun risque de cannibalisation d'une offre.
A3: Chaque poste porte son propre taux d'évitement. Cellules jaunes = saisie.
A5: Poste de coût du service historique | B5: Coût annuel actuel (XPF) | C5: Evité Prudent | D5: Evité Central | E5: Evité Ambitieux | F5: Confiance | G5: Justification du taux d'évitement
A6: Hébergement et infrastructure on-premise allouée | B6: 1800000 | C6: 0.75 | D6: 0.85 | E6: 0.95 | F6: A VALIDER OPT | G6: Bascule vers un socle conteneurisé mutualisé. Quote-part serveurs, stockage, sauvegarde et supervision du service historique.
A7: TMA et maintenance corrective | B7: 3600000 | C7: 0.72 | D7: 0.8 | E7: 0.9 | F7: A VALIDER OPT | G7: Poste le plus lourd du legacy. Remplaçé par une stack open source maintenue en continu, avec tests automatisés et déploiement reproductible.
A8: Exploitation interne (0,25 ETP) | B8: 2000000 | C8: 0.6 | D8: 0.75 | E8: 0.85 | F8: A VALIDER OPT | G8: Supervision, redémarrages, gestion des incidents et des évolutions mineures. Automatisée par l'observabilité et les déploiements sans interruption.
A9: Support N1/N2 : abus, réclamations, signalements | B9: 900000 | C9: 0.6 | D9: 0.75 | E9: 0.9 | F9: Moyenne | G9: Directement réduit par le dispositif de confiance sur le canal 1000 : vérification d'origine d'un Mobitag, signalement en un clic, maîtrise par le destinataire. C'est la contribution économique de la ligne F11.
A10: Licences et composants propriétaires | B10: 450000 | C10: 0.85 | D10: 0.95 | E10: 1 | F10: Moyenne | G10: Supprimées par l'exigence open source du challenge. Evitement quasi total par construction.
A11: Acheminement des SMS du service historique | B11: 700000 | C11: 1 | D11: 1 | E11: 1 | F11: A VALIDER OPT | G11: Charge reprise A L'IDENTIQUE par le service refondu, où elle figure en coût variable. Neutre au différentiel : présentée des deux côtés pour que le comparatif soit auditable et qu'aucun coût du socle gratuit ne soit dissimulé.
A12: TOTAL COUT COMPLET ANNUEL ACTUEL | B12: =SUM(B6:B11)
A13: ECONOMIE ANNUELLE RETENUE (régime établi) | C13: =SUMPRODUCT($B$6:$B$11,C6:C11) | D13: =SUMPRODUCT($B$6:$B$11,D6:D11) | E13: =SUMPRODUCT($B$6:$B$11,E6:E11)
A14: Economie mensuelle en régime établi | C14: =C13/12 | D14: =D13/12 | E14: =E13/12
A15: Taux d'évitement global | C15: =C13/$B$12 | D15: =D13/$B$12 | E15: =E13/$B$12
A17: Absence de double comptage : les coûts évités ci-dessus correspondent à l'ARRET du service historique.
A18: Les coûts d'exploitation du service refondu (run, cloud, support, communication) sont portés séparément en coûts fixes dans les onglets 4 à 6. Le modèle ne compte donc jamais deux fois la même charge.
A19: La réalisation de ces économies débute au mois de bascule (hypothèse 'switch') et monte linéairement sur la durée de double run (hypothèse 'switchramp').

Sheet 3_Unit_economics
A1: UNIT ECONOMICS ET RATIOS DE CONTROLE
A2: Valeurs calculées au mois 24. Montants en XPF HT.
A4: Indicateur | B4: Unité | C4: Prudent | D4: Central | E4: Ambitieux | F4: Lecture
A5: COUT DE REVIENT DU SOCLE GRATUIT
A6: Coût variable d'un SMS gratuit envoyé | B6: XPF/SMS | C6: ='1_Hypotheses'!$C$33 | D6: ='1_Hypotheses'!$D$33 | E6: ='1_Hypotheses'!$E$33 | F6: Coût marginal d'acheminement. Reste à la charge du service : le socle gratuit n'est jamais facturé.
A7: Coût complet mensuel du socle gratuit par MAU | B7: XPF/MAU | C7: =-('4_PL_Prudent'!Z25+'4_PL_Prudent'!Z41)/'4_PL_Prudent'!Z7 | D7: =-('5_PL_Central'!Z25+'5_PL_Central'!Z41)/'5_PL_Central'!Z7 | E7: =-('6_PL_Ambitieux'!Z25+'6_PL_Ambitieux'!Z41)/'6_PL_Ambitieux'!Z7 | F7: Coûts variables et fixes rapportés à l'utilisateur actif au mois 24. Mesure la sobriété du service refondu.
A8: Coût complet annuel du socle gratuit | B8: XPF/an | C8: =-('4_PL_Prudent'!Z25+'4_PL_Prudent'!Z41)*12 | D8: =-('5_PL_Central'!Z25+'5_PL_Central'!Z41)*12 | E8: =-('6_PL_Ambitieux'!Z25+'6_PL_Ambitieux'!Z41)*12 | F8: A comparer au coût complet actuel du service, onglet 2.
A9: VALEUR DES APPORTS D'AFFAIRES
A10: Valeur annuelle attribuée d'un client Helia PRO apporté | B10: XPF/an | C10: ='1_Hypotheses'!$C$15*'1_Hypotheses'!$C$16 | D10: ='1_Hypotheses'!$D$15*'1_Hypotheses'!$D$16 | E10: ='1_Hypotheses'!$E$15*'1_Hypotheses'!$E$16 | F10: Marge annuelle moyenne multipliée par le taux d'attribution. Attribution volontairement partielle.
A11: Durée de vie moyenne d'un compte PRO apporté | B11: mois | C11: =1/'1_Hypotheses'!$C$17 | D11: =1/'1_Hypotheses'!$D$17 | E11: =1/'1_Hypotheses'!$E$17 | F11: Inverse de l'attrition mensuelle.
A12: Valeur vie attribuée d'un client Helia PRO | B12: XPF | C12: ='1_Hypotheses'!$C$15/12*'1_Hypotheses'!$C$16/'1_Hypotheses'!$C$17 | D12: ='1_Hypotheses'!$D$15/12*'1_Hypotheses'!$D$16/'1_Hypotheses'!$D$17 | E12: ='1_Hypotheses'!$E$15/12*'1_Hypotheses'!$E$16/'1_Hypotheses'!$E$17 | F12: LTV attribuée au service Mobitag NG.
A13: Valeur vie attribuée d'une ligne grand public | B13: XPF | C13: ='1_Hypotheses'!$C$23/12*'1_Hypotheses'!$C$24/'1_Hypotheses'!$C$25 | D13: ='1_Hypotheses'!$D$23/12*'1_Hypotheses'!$D$24/'1_Hypotheses'!$D$25 | E13: ='1_Hypotheses'!$E$23/12*'1_Hypotheses'!$E$24/'1_Hypotheses'!$E$25 | F13: Idem côté activation de lignes.
A14: Coût d'acquisition d'un apport (CAC proxy) | B14: XPF | C14: =-('1_Hypotheses'!$C$40*24)/('4_PL_Prudent'!B12+'4_PL_Prudent'!B14) | D14: =-('1_Hypotheses'!$D$40*24)/('5_PL_Central'!B12+'5_PL_Central'!B14) | E14: =-('1_Hypotheses'!$E$40*24)/('6_PL_Ambitieux'!B12+'6_PL_Ambitieux'!B14) | F14: Budget communication sur 24 mois rapporté au nombre total d'apports générés.
A15: Ratio LTV / CAC (apports B2C) | B15: x | C15: =('1_Hypotheses'!$C$23/12*'1_Hypotheses'!$C$24/'1_Hypotheses'!$C$25)/(-('1_Hypotheses'!$C$40*24)/('4_PL_Prudent'!B12+'4_PL_Prudent'!B14)) | D15: =('1_Hypotheses'!$D$23/12*'1_Hypotheses'!$D$24/'1_Hypotheses'!$D$25)/(-('1_Hypotheses'!$D$40*24)/('5_PL_Central'!B12+'5_PL_Central'!B14)) | E15: =('1_Hypotheses'!$E$23/12*'1_Hypotheses'!$E$24/'1_Hypotheses'!$E$25)/(-('1_Hypotheses'!$E$40*24)/('6_PL_Ambitieux'!B12+'6_PL_Ambitieux'!B14)) | F15: Au-dessus de 3, l'acquisition est saine. Sert de garde-fou au budget communication.
A16: STRUCTURE ECONOMIQUE AU MOIS 24
A17: Part des coûts évités dans l'équilibre | B17: % | C17: ='4_PL_Prudent'!Z35/('4_PL_Prudent'!Z35+'4_PL_Prudent'!Z26) | D17: ='5_PL_Central'!Z35/('5_PL_Central'!Z35+'5_PL_Central'!Z26) | E17: ='6_PL_Ambitieux'!Z35/('6_PL_Ambitieux'!Z35+'6_PL_Ambitieux'!Z26) | F17: Mesure la dépendance du modèle au levier économies. Volontairement majoritaire : c'est le levier le plus certain et le seul totalement non redondant.
A18: Part des apports d'affaires dans l'équilibre | B18: % | C18: ='4_PL_Prudent'!Z26/('4_PL_Prudent'!Z35+'4_PL_Prudent'!Z26) | D18: ='5_PL_Central'!Z26/('5_PL_Central'!Z35+'5_PL_Central'!Z26) | E18: ='6_PL_Ambitieux'!Z26/('6_PL_Ambitieux'!Z35+'6_PL_Ambitieux'!Z26) | F18: Contribution des lignes B2B et B2C, sponsoring inclus.
A19: Taux de couverture des coûts fixes | B19: % | C19: =('4_PL_Prudent'!Z26+'4_PL_Prudent'!Z35)/-'4_PL_Prudent'!Z41 | D19: =('5_PL_Central'!Z26+'5_PL_Central'!Z35)/-'5_PL_Central'!Z41 | E19: =('6_PL_Ambitieux'!Z26+'6_PL_Ambitieux'!Z35)/-'6_PL_Ambitieux'!Z41 | F19: Au-dessus de 100 %, le service s'autofinance hors investissement.
A20: Marge contributive annualisée | B20: XPF/an | C20: ='4_PL_Prudent'!Z26*12 | D20: ='5_PL_Central'!Z26*12 | E20: ='6_PL_Ambitieux'!Z26*12 | F20: Marge contributive du mois 24 annualisée.

Sheet 4_PL_Prudent
A1: COMPTE DE RESULTAT MENSUEL 24 MOIS - SCENARIO PRUDENT
A2: Montants en XPF HT. Vue service Mobitag Nouvelle Génération (périmètre OPT-NC).
A3: Aucune ligne de revenu issue de la vente de volume SMS au particulier.
A5: Poste | B5: Total 24M | C5: M1 | D5: M2 | E5: M3 | F5: M4 | G5: M5 | H5: M6 | I5: M7 | J5: M8 | K5: M9 | L5: M10 | M5: M11 | N5: M12 | O5: M13 | P5: M14 | Q5: M15 | R5: M16 | S5: M17 | T5: M18 | U5: M19 | V5: M20 | W5: M21 | X5: M22 | Y5: M23 | Z5: M24
A6: VOLUMETRIE
A7: Utilisateurs actifs mensuels (MAU) | B7: =Z7 | C7: ='1_Hypotheses'!$C$7 | D7: =MIN('1_Hypotheses'!$C$9,C7*(1+'1_Hypotheses'!$C$8)) | E7: =MIN('1_Hypotheses'!$C$9,D7*(1+'1_Hypotheses'!$C$8)) | F7: =MIN('1_Hypotheses'!$C$9,E7*(1+'1_Hypotheses'!$C$8)) | G7: =MIN('1_Hypotheses'!$C$9,F7*(1+'1_Hypotheses'!$C$8)) | H7: =MIN('1_Hypotheses'!$C$9,G7*(1+'1_Hypotheses'!$C$8)) | I7: =MIN('1_Hypotheses'!$C$9,H7*(1+'1_Hypotheses'!$C$8)) | J7: =MIN('1_Hypotheses'!$C$9,I7*(1+'1_Hypotheses'!$C$8)) | K7: =MIN('1_Hypotheses'!$C$9,J7*(1+'1_Hypotheses'!$C$8)) | ... Z7: =MIN('1_Hypotheses'!$C$9,Y7*(1+'1_Hypotheses'!$C$8))
A8: SMS gratuits envoyés | B8: =SUM(C8:Z8) | C8: =C7*'1_Hypotheses'!$C$10 | D8: =D7*'1_Hypotheses'!$C$10 | E8: =E7*'1_Hypotheses'!$C$10 | F8: =F7*'1_Hypotheses'!$C$10 | G8: =G7*'1_Hypotheses'!$C$10 | H8: =H7*'1_Hypotheses'!$C$10 | I8: =I7*'1_Hypotheses'!$C$10 | J8: =J7*'1_Hypotheses'!$C$10 | ... Z8: =Z7*'1_Hypotheses'!$C$10
A9: Usages professionnels détectés | B9: =SUM(C9:Z9) | C9: =C7*'1_Hypotheses'!$C$12 | D9: =D7*'1_Hypotheses'!$C$12 | E9: =E7*'1_Hypotheses'!$C$12 | F9: =F7*'1_Hypotheses'!$C$12 | G9: =G7*'1_Hypotheses'!$C$12 | H9: =H7*'1_Hypotheses'!$C$12 | I9: =I7*'1_Hypotheses'!$C$12 | J9: =J7*'1_Hypotheses'!$C$12 | ... Z9: =Z7*'1_Hypotheses'!$C$12
A10: Utilisateurs sans ligne active détectés | B10: =SUM(C10:Z10) | C10: =C7*'1_Hypotheses'!$C$20 | D10: =D7*'1_Hypotheses'!$C$20 | E10: =E7*'1_Hypotheses'!$C$20 | F10: =F7*'1_Hypotheses'!$C$20 | G10: =G7*'1_Hypotheses'!$C$20 | H10: =H7*'1_Hypotheses'!$C$20 | I10: =I7*'1_Hypotheses'!$C$20 | J10: =J7*'1_Hypotheses'!$C$20 | ... Z10: =Z7*'1_Hypotheses'!$C$20
A11: APPORTS D'AFFAIRES - CONSTITUTION DES STOCKS
A12: Nouveaux clients Helia PRO apportés | B12: =SUM(C12:Z12) | C12: =IF(1>='1_Hypotheses'!$C$18,C9*'1_Hypotheses'!$C$13*'1_Hypotheses'!$C$14,0) | D12: =IF(2>='1_Hypotheses'!$C$18,D9*'1_Hypotheses'!$C$13*'1_Hypotheses'!$C$14,0) | E12: =IF(3>='1_Hypotheses'!$C$18,E9*'1_Hypotheses'!$C$13*'1_Hypotheses'!$C$14,0) | F12: =IF(4>='1_Hypotheses'!$C$18,F9*'1_Hypotheses'!$C$13*'1_Hypotheses'!$C$14,0) | G12: =IF(5>='1_Hypotheses'!$C$18,G9*'1_Hypotheses'!$C$13*'1_Hypotheses'!$C$14,0) | H12: =IF(6>='1_Hypotheses'!$C$18,H9*'1_Hypotheses'!$C$13*'1_Hypotheses'!$C$14,0) | I12: =IF(7>='1_Hypotheses'!$C$18,I9*'1_Hypotheses'!$C$13*'1_Hypotheses'!$C$14,0) | J12: =IF(8>='1_Hypotheses'!$C$18,J9*'1_Hypotheses'!$C$13*'1_Hypotheses'!$C$14,0) | K12: =IF(9>='1_Hypotheses'!$C$18,K9*'1_Hypotheses'!$C$13*'1_Hypotheses'!$C$14,0) | L12: =IF(10>='1_Hypotheses'!$C$18,L9*'1_Hypotheses'!$C$13*'1_Hypotheses'!$C$14,0) | M12: =IF(11>='1_Hypotheses'!$C$18,M9*'1_Hypotheses'!$C$13*'1_Hypotheses'!$C$14,0) | N12: =IF(12>='1_Hypotheses'!$C$18,N9*'1_Hypotheses'!$C$13*'1_Hypotheses'!$C$14,0) | O12: =IF(13>='1_Hypotheses'!$C$18,O9*'1_Hypotheses'!$C$13*'1_Hypotheses'!$C$14,0) | P12: =IF(14>='1_Hypotheses'!$C$18,P9*'1_Hypotheses'!$C$13*'1_Hypotheses'!$C$14,0) | Q12: =IF(15>='1_Hypotheses'!$C$18,Q9*'1_Hypotheses'!$C$13*'1_Hypotheses'!$C$14,0) | R12: =IF(16>='1_Hypotheses'!$C$18,R9*'1_Hypotheses'!$C$13*'1_Hypotheses'!$C$14,0) | S12: =IF(17>='1_Hypotheses'!$C$18,S9*'1_Hypotheses'!$C$13*'1_Hypotheses'!$C$14,0) | T12: =IF(18>='1_Hypotheses'!$C$18,T9*'1_Hypotheses'!$C$13*'1_Hypotheses'!$C$14,0) | U12: =IF(19>='1_Hypotheses'!$C$18,U9*'1_Hypotheses'!$C$13*'1_Hypotheses'!$C$14,0) | V12: =IF(20>='1_Hypotheses'!$C$18,V9*'1_Hypotheses'!$C$13*'1_Hypotheses'!$C$14,0) | W12: =IF(21>='1_Hypotheses'!$C$18,W9*'1_Hypotheses'!$C$13*'1_Hypotheses'!$C$14,0) | X12: =IF(22>='1_Hypotheses'!$C$18,X9*'1_Hypotheses'!$C$13*'1_Hypotheses'!$C$14,0) | Y12: =IF(23>='1_Hypotheses'!$C$18,Y9*'1_Hypotheses'!$C$13*'1_Hypotheses'!$C$14,0) | Z12: =IF(24>='1_Hypotheses'!$C$18,Z9*'1_Hypotheses'!$C$13*'1_Hypotheses'!$C$14,0)
A13: Stock de clients Helia PRO apportés | B13: =Z13 | C13: =C12 | D13: =C13*(1-'1_Hypotheses'!$C$17)+D12 | E13: =D13*(1-'1_Hypotheses'!$C$17)+E12 | F13: =E13*(1-'1_Hypotheses'!$C$17)+F12 | G13: =F13*(1-'1_Hypotheses'!$C$17)+G12 | H13: =G13*(1-'1_Hypotheses'!$C$17)+H12 | I13: =H13*(1-'1_Hypotheses'!$C$17)+I12 | J13: =I13*(1-'1_Hypotheses'!$C$17)+J12 | K13: =J13*(1-'1_Hypotheses'!$C$17)+K12 | ... Z13: =Y13*(1-'1_Hypotheses'!$C$17)+Z12
A14: Nouvelles lignes grand public activées | B14: =SUM(C14:Z14) | C14: =IF(1>='1_Hypotheses'!$C$26,C10*'1_Hypotheses'!$C$21*'1_Hypotheses'!$C$22,0) | D14: =IF(2>='1_Hypotheses'!$C$26,D10*'1_Hypotheses'!$C$21*'1_Hypotheses'!$C$22,0) | E14: =IF(3>='1_Hypotheses'!$C$26,E10*'1_Hypotheses'!$C$21*'1_Hypotheses'!$C$22,0) | F14: =IF(4>='1_Hypotheses'!$C$26,F10*'1_Hypotheses'!$C$21*'1_Hypotheses'!$C$22,0) | G14: =IF(5>='1_Hypotheses'!$C$26,G10*'1_Hypotheses'!$C$21*'1_Hypotheses'!$C$22,0) | H14: =IF(6>='1_Hypotheses'!$C$26,H10*'1_Hypotheses'!$C$21*'1_Hypotheses'!$C$22,0) | I14: =IF(7>='1_Hypotheses'!$C$26,I10*'1_Hypotheses'!$C$21*'1_Hypotheses'!$C$22,0) | J14: =IF(8>='1_Hypotheses'!$C$26,J10*'1_Hypotheses'!$C$21*'1_Hypotheses'!$C$22,0) | K14: =IF(9>='1_Hypotheses'!$C$26,K10*'1_Hypotheses'!$C$21*'1_Hypotheses'!$C$22,0) | L14: =IF(10>='1_Hypotheses'!$C$26,L10*'1_Hypotheses'!$C$21*'1_Hypotheses'!$C$22,0) | M14: =IF(11>='1_Hypotheses'!$C$26,M10*'1_Hypotheses'!$C$21*'1_Hypotheses'!$C$22,0) | N14: =IF(12>='1_Hypotheses'!$C$26,N10*'1_Hypotheses'!$C$21*'1_Hypotheses'!$C$22,0) | O14: =IF(13>='1_Hypotheses'!$C$26,O10*'1_Hypotheses'!$C$21*'1_Hypotheses'!$C$22,0) | P14: =IF(14>='1_Hypotheses'!$C$26,P10*'1_Hypotheses'!$C$21*'1_Hypotheses'!$C$22,0) | Q14: =IF(15>='1_Hypotheses'!$C$26,Q10*'1_Hypotheses'!$C$21*'1_Hypotheses'!$C$22,0) | R14: =IF(16>='1_Hypotheses'!$C$26,R10*'1_Hypotheses'!$C$21*'1_Hypotheses'!$C$22,0) | S14: =IF(17>='1_Hypotheses'!$C$26,S10*'1_Hypotheses'!$C$21*'1_Hypotheses'!$C$22,0) | T14: =IF(18>='1_Hypotheses'!$C$26,T10*'1_Hypotheses'!$C$21*'1_Hypotheses'!$C$22,0) | U14: =IF(19>='1_Hypotheses'!$C$26,U10*'1_Hypotheses'!$C$21*'1_Hypotheses'!$C$22,0) | V14: =IF(20>='1_Hypotheses'!$C$26,V10*'1_Hypotheses'!$C$21*'1_Hypotheses'!$C$22,0) | W14: =IF(21>='1_Hypotheses'!$C$26,W10*'1_Hypotheses'!$C$21*'1_Hypotheses'!$C$22,0) | X14: =IF(22>='1_Hypotheses'!$C$26,X10*'1_Hypotheses'!$C$21*'1_Hypotheses'!$C$22,0) | Y14: =IF(23>='1_Hypotheses'!$C$26,Y10*'1_Hypotheses'!$C$21*'1_Hypotheses'!$C$22,0) | Z14: =IF(24>='1_Hypotheses'!$C$26,Z10*'1_Hypotheses'!$C$21*'1_Hypotheses'!$C$22,0)
A15: Stock de lignes grand public apportées | B15: =Z15 | C15: =C14 | D15: =C15*(1-'1_Hypotheses'!$C$25)+D14 | E15: =D15*(1-'1_Hypotheses'!$C$25)+E14 | F15: =E15*(1-'1_Hypotheses'!$C$25)+F14 | G15: =F15*(1-'1_Hypotheses'!$C$25)+G14 | H15: =G15*(1-'1_Hypotheses'!$C$25)+H14 | I15: =H15*(1-'1_Hypotheses'!$C$25)+I14 | J15: =I15*(1-'1_Hypotheses'!$C$25)+J14 | K15: =J15*(1-'1_Hypotheses'!$C$25)+K14 | ... Z15: =Y15*(1-'1_Hypotheses'!$C$25)+Z14
A16: CHIFFRE D'AFFAIRES / VALEUR CREEE
A17: Apport d'affaires B2B - Helia PRO | B17: =SUM(C17:Z17) | C17: =C13*'1_Hypotheses'!$C$15/12*'1_Hypotheses'!$C$16 | D17: =D13*'1_Hypotheses'!$C$15/12*'1_Hypotheses'!$C$16 | E17: =E13*'1_Hypotheses'!$C$15/12*'1_Hypotheses'!$C$16 | F17: =F13*'1_Hypotheses'!$C$15/12*'1_Hypotheses'!$C$16 | G17: =G13*'1_Hypotheses'!$C$15/12*'1_Hypotheses'!$C$16 | H17: =H13*'1_Hypotheses'!$C$15/12*'1_Hypotheses'!$C$16 | I17: =I13*'1_Hypotheses'!$C$15/12*'1_Hypotheses'!$C$16 | J17: =J13*'1_Hypotheses'!$C$15/12*'1_Hypotheses'!$C$16 | ... Z17: =Z13*'1_Hypotheses'!$C$15/12*'1_Hypotheses'!$C$16
A18: Apport d'affaires B2C - activation de lignes | B18: =SUM(C18:Z18) | C18: =C15*'1_Hypotheses'!$C$23/12*'1_Hypotheses'!$C$24 | D18: =D15*'1_Hypotheses'!$C$23/12*'1_Hypotheses'!$C$24 | E18: =E15*'1_Hypotheses'!$C$23/12*'1_Hypotheses'!$C$24 | F18: =F15*'1_Hypotheses'!$C$23/12*'1_Hypotheses'!$C$24 | G18: =G15*'1_Hypotheses'!$C$23/12*'1_Hypotheses'!$C$24 | H18: =H15*'1_Hypotheses'!$C$23/12*'1_Hypotheses'!$C$24 | I18: =I15*'1_Hypotheses'!$C$23/12*'1_Hypotheses'!$C$24 | J18: =J15*'1_Hypotheses'!$C$23/12*'1_Hypotheses'!$C$24 | ... Z18: =Z15*'1_Hypotheses'!$C$23/12*'1_Hypotheses'!$C$24
A19: Sponsoring consenti | B19: =SUM(C19:Z19) | C19: =IF(1<'1_Hypotheses'!$C$29,0,'1_Hypotheses'!$C$28*MIN(1,(1-'1_Hypotheses'!$C$29+1)/'1_Hypotheses'!$C$30)) | D19: =IF(2<'1_Hypotheses'!$C$29,0,'1_Hypotheses'!$C$28*MIN(1,(2-'1_Hypotheses'!$C$29+1)/'1_Hypotheses'!$C$30)) | E19: =IF(3<'1_Hypotheses'!$C$29,0,'1_Hypotheses'!$C$28*MIN(1,(3-'1_Hypotheses'!$C$29+1)/'1_Hypotheses'!$C$30)) | F19: =IF(4<'1_Hypotheses'!$C$29,0,'1_Hypotheses'!$C$28*MIN(1,(4-'1_Hypotheses'!$C$29+1)/'1_Hypotheses'!$C$30)) | G19: =IF(5<'1_Hypotheses'!$C$29,0,'1_Hypotheses'!$C$28*MIN(1,(5-'1_Hypotheses'!$C$29+1)/'1_Hypotheses'!$C$30)) | H19: =IF(6<'1_Hypotheses'!$C$29,0,'1_Hypotheses'!$C$28*MIN(1,(6-'1_Hypotheses'!$C$29+1)/'1_Hypotheses'!$C$30)) | I19: =IF(7<'1_Hypotheses'!$C$29,0,'1_Hypotheses'!$C$28*MIN(1,(7-'1_Hypotheses'!$C$29+1)/'1_Hypotheses'!$C$30)) | J19: =IF(8<'1_Hypotheses'!$C$29,0,'1_Hypotheses'!$C$28*MIN(1,(8-'1_Hypotheses'!$C$29+1)/'1_Hypotheses'!$C$30)) | K19: =IF(9<'1_Hypotheses'!$C$29,0,'1_Hypotheses'!$C$28*MIN(1,(9-'1_Hypotheses'!$C$29+1)/'1_Hypotheses'!$C$30)) | L19: =IF(10<'1_Hypotheses'!$C$29,0,'1_Hypotheses'!$C$28*MIN(1,(10-'1_Hypotheses'!$C$29+1)/'1_Hypotheses'!$C$30)) | M19: =IF(11<'1_Hypotheses'!$C$29,0,'1_Hypotheses'!$C$28*MIN(1,(11-'1_Hypotheses'!$C$29+1)/'1_Hypotheses'!$C$30)) | N19: =IF(12<'1_Hypotheses'!$C$29,0,'1_Hypotheses'!$C$28*MIN(1,(12-'1_Hypotheses'!$C$29+1)/'1_Hypotheses'!$C$30)) | O19: =IF(13<'1_Hypotheses'!$C$29,0,'1_Hypotheses'!$C$28*MIN(1,(13-'1_Hypotheses'!$C$29+1)/'1_Hypotheses'!$C$30)) | P19: =IF(14<'1_Hypotheses'!$C$29,0,'1_Hypotheses'!$C$28*MIN(1,(14-'1_Hypotheses'!$C$29+1)/'1_Hypotheses'!$C$30)) | Q19: =IF(15<'1_Hypotheses'!$C$29,0,'1_Hypotheses'!$C$28*MIN(1,(15-'1_Hypotheses'!$C$29+1)/'1_Hypotheses'!$C$30)) | R19: =IF(16<'1_Hypotheses'!$C$29,0,'1_Hypotheses'!$C$28*MIN(1,(16-'1_Hypotheses'!$C$29+1)/'1_Hypotheses'!$C$30)) | S19: =IF(17<'1_Hypotheses'!$C$29,0,'1_Hypotheses'!$C$28*MIN(1,(17-'1_Hypotheses'!$C$29+1)/'1_Hypotheses'!$C$30)) | T19: =IF(18<'1_Hypotheses'!$C$29,0,'1_Hypotheses'!$C$28*MIN(1,(18-'1_Hypotheses'!$C$29+1)/'1_Hypotheses'!$C$30)) | U19: =IF(19<'1_Hypotheses'!$C$29,0,'1_Hypotheses'!$C$28*MIN(1,(19-'1_Hypotheses'!$C$29+1)/'1_Hypotheses'!$C$30)) | V19: =IF(20<'1_Hypotheses'!$C$29,0,'1_Hypotheses'!$C$28*MIN(1,(20-'1_Hypotheses'!$C$29+1)/'1_Hypotheses'!$C$30)) | W19: =IF(21<'1_Hypotheses'!$C$29,0,'1_Hypotheses'!$C$28*MIN(1,(21-'1_Hypotheses'!$C$29+1)/'1_Hypotheses'!$C$30)) | X19: =IF(22<'1_Hypotheses'!$C$29,0,'1_Hypotheses'!$C$28*MIN(1,(22-'1_Hypotheses'!$C$29+1)/'1_Hypotheses'!$C$30)) | Y19: =IF(23<'1_Hypotheses'!$C$29,0,'1_Hypotheses'!$C$28*MIN(1,(23-'1_Hypotheses'!$C$29+1)/'1_Hypotheses'!$C$30)) | Z19: =IF(24<'1_Hypotheses'!$C$29,0,'1_Hypotheses'!$C$28*MIN(1,(24-'1_Hypotheses'!$C$29+1)/'1_Hypotheses'!$C$30))
A20: CHIFFRE D'AFFAIRES TOTAL | B20: =SUM(C20:Z20) | C20: =SUM(C17:C19) | D20: =SUM(D17:D19) | E20: =SUM(E17:E19) | F20: =SUM(F17:F19) | G20: =SUM(G17:G19) | H20: =SUM(H17:H19) | I20: =SUM(I17:I19) | J20: =SUM(J17:J19) | ... Z20: =SUM(Z17:Z19)
A21: COUTS VARIABLES ET REVERSEMENTS
A22: Acheminement des SMS gratuits | B22: =SUM(C22:Z22) | C22: =-C8*'1_Hypotheses'!$C$33 | D22: =-D8*'1_Hypotheses'!$C$33 | E22: =-E8*'1_Hypotheses'!$C$33 | F22: =-F8*'1_Hypotheses'!$C$33 | G22: =-G8*'1_Hypotheses'!$C$33 | H22: =-H8*'1_Hypotheses'!$C$33 | I22: =-I8*'1_Hypotheses'!$C$33 | J22: =-J8*'1_Hypotheses'!$C$33 | ... Z22: =-Z8*'1_Hypotheses'!$C$33
A23: Infrastructure variable | B23: =SUM(C23:Z23) | C23: =-C7*'1_Hypotheses'!$C$34 | D23: =-D7*'1_Hypotheses'!$C$34 | E23: =-E7*'1_Hypotheses'!$C$34 | F23: =-F7*'1_Hypotheses'!$C$34 | G23: =-G7*'1_Hypotheses'!$C$34 | H23: =-H7*'1_Hypotheses'!$C$34 | I23: =-I7*'1_Hypotheses'!$C$34 | J23: =-J7*'1_Hypotheses'!$C$34 | ... Z23: =-Z7*'1_Hypotheses'!$C$34
A24: Reversement régie sponsoring | B24: =SUM(C24:Z24) | C24: =-C19*'1_Hypotheses'!$C$31 | D24: =-D19*'1_Hypotheses'!$C$31 | E24: =-E19*'1_Hypotheses'!$C$31 | F24: =-F19*'1_Hypotheses'!$C$31 | G24: =-G19*'1_Hypotheses'!$C$31 | H24: =-H19*'1_Hypotheses'!$C$31 | I24: =-I19*'1_Hypotheses'!$C$31 | J24: =-J19*'1_Hypotheses'!$C$31 | ... Z24: =-Z19*'1_Hypotheses'!$C$31
A25: TOTAL COUTS VARIABLES ET REVERSEMENTS | B25: =SUM(C25:Z25) | C25: =SUM(C22:C24) | D25: =SUM(D22:D24) | E25: =SUM(E22:E24) | F25: =SUM(F22:F24) | G25: =SUM(G22:G24) | H25: =SUM(H22:H24) | I25: =SUM(I22:I24) | J25: =SUM(J22:J24) | ... Z25: =SUM(Z22:Z24)
A26: MARGE CONTRIBUTIVE | B26: =SUM(C26:Z26) | C26: =C20+C25 | D26: =D20+D25 | E26: =E20+E25 | F26: =F20+F25 | G26: =G20+G25 | H26: =H20+H25 | I26: =I20+I25 | J26: =J20+J25 | ... Z26: =Z20+Z25
A27: COUTS EVITES (arrêt du service historique)
A28: Taux de réalisation des économies | B28: =Z28 | C28: =IF(1<'1_Hypotheses'!$C$48,0,MIN(1,(1-'1_Hypotheses'!$C$48+1)/'1_Hypotheses'!$C$49)) | D28: =IF(2<'1_Hypotheses'!$C$48,0,MIN(1,(2-'1_Hypotheses'!$C$48+1)/'1_Hypotheses'!$C$49)) | E28: =IF(3<'1_Hypotheses'!$C$48,0,MIN(1,(3-'1_Hypotheses'!$C$48+1)/'1_Hypotheses'!$C$49)) | F28: =IF(4<'1_Hypotheses'!$C$48,0,MIN(1,(4-'1_Hypotheses'!$C$48+1)/'1_Hypotheses'!$C$49)) | G28: =IF(5<'1_Hypotheses'!$C$48,0,MIN(1,(5-'1_Hypotheses'!$C$48+1)/'1_Hypotheses'!$C$49)) | H28: =IF(6<'1_Hypotheses'!$C$48,0,MIN(1,(6-'1_Hypotheses'!$C$48+1)/'1_Hypotheses'!$C$49)) | I28: =IF(7<'1_Hypotheses'!$C$48,0,MIN(1,(7-'1_Hypotheses'!$C$48+1)/'1_Hypotheses'!$C$49)) | J28: =IF(8<'1_Hypotheses'!$C$48,0,MIN(1,(8-'1_Hypotheses'!$C$48+1)/'1_Hypotheses'!$C$49)) | K28: =IF(9<'1_Hypotheses'!$C$48,0,MIN(1,(9-'1_Hypotheses'!$C$48+1)/'1_Hypotheses'!$C$49)) | L28: =IF(10<'1_Hypotheses'!$C$48,0,MIN(1,(10-'1_Hypotheses'!$C$48+1)/'1_Hypotheses'!$C$49)) | M28: =IF(11<'1_Hypotheses'!$C$48,0,MIN(1,(11-'1_Hypotheses'!$C$48+1)/'1_Hypotheses'!$C$49)) | N28: =IF(12<'1_Hypotheses'!$C$48,0,MIN(1,(12-'1_Hypotheses'!$C$48+1)/'1_Hypotheses'!$C$49)) | O28: =IF(13<'1_Hypotheses'!$C$48,0,MIN(1,(13-'1_Hypotheses'!$C$48+1)/'1_Hypotheses'!$C$49)) | P28: =IF(14<'1_Hypotheses'!$C$48,0,MIN(1,(14-'1_Hypotheses'!$C$48+1)/'1_Hypotheses'!$C$49)) | Q28: =IF(15<'1_Hypotheses'!$C$48,0,MIN(1,(15-'1_Hypotheses'!$C$48+1)/'1_Hypotheses'!$C$49)) | R28: =IF(16<'1_Hypotheses'!$C$48,0,MIN(1,(16-'1_Hypotheses'!$C$48+1)/'1_Hypotheses'!$C$49)) | S28: =IF(17<'1_Hypotheses'!$C$48,0,MIN(1,(17-'1_Hypotheses'!$C$48+1)/'1_Hypotheses'!$C$49)) | T28: =IF(18<'1_Hypotheses'!$C$48,0,MIN(1,(18-'1_Hypotheses'!$C$48+1)/'1_Hypotheses'!$C$49)) | U28: =IF(19<'1_Hypotheses'!$C$48,0,MIN(1,(19-'1_Hypotheses'!$C$48+1)/'1_Hypotheses'!$C$49)) | V28: =IF(20<'1_Hypotheses'!$C$48,0,MIN(1,(20-'1_Hypotheses'!$C$48+1)/'1_Hypotheses'!$C$49)) | W28: =IF(21<'1_Hypotheses'!$C$48,0,MIN(1,(21-'1_Hypotheses'!$C$48+1)/'1_Hypotheses'!$C$49)) | X28: =IF(22<'1_Hypotheses'!$C$48,0,MIN(1,(22-'1_Hypotheses'!$C$48+1)/'1_Hypotheses'!$C$49)) | Y28: =IF(23<'1_Hypotheses'!$C$48,0,MIN(1,(23-'1_Hypotheses'!$C$48+1)/'1_Hypotheses'!$C$49)) | Z28: =IF(24<'1_Hypotheses'!$C$48,0,MIN(1,(24-'1_Hypotheses'!$C$48+1)/'1_Hypotheses'!$C$49))
A29: Hébergement et infrastructure on-premise allouée | B29: =SUM(C29:Z29) | C29: ='2_Couts_evites'!$B$6*'2_Couts_evites'!$C$6/12*C28 | D29: ='2_Couts_evites'!$B$6*'2_Couts_evites'!$C$6/12*D28 | E29: ='2_Couts_evites'!$B$6*'2_Couts_evites'!$C$6/12*E28 | F29: ='2_Couts_evites'!$B$6*'2_Couts_evites'!$C$6/12*F28 | G29: ='2_Couts_evites'!$B$6*'2_Couts_evites'!$C$6/12*G28 | H29: ='2_Couts_evites'!$B$6*'2_Couts_evites'!$C$6/12*H28 | I29: ='2_Couts_evites'!$B$6*'2_Couts_evites'!$C$6/12*I28 | J29: ='2_Couts_evites'!$B$6*'2_Couts_evites'!$C$6/12*J28 | ... Z29: ='2_Couts_evites'!$B$6*'2_Couts_evites'!$C$6/12*Z28
A30: TMA et maintenance corrective | B30: =SUM(C30:Z30) | C30: ='2_Couts_evites'!$B$7*'2_Couts_evites'!$C$7/12*C28 | D30: ='2_Couts_evites'!$B$7*'2_Couts_evites'!$C$7/12*D28 | E30: ='2_Couts_evites'!$B$7*'2_Couts_evites'!$C$7/12*E28 | F30: ='2_Couts_evites'!$B$7*'2_Couts_evites'!$C$7/12*F28 | G30: ='2_Couts_evites'!$B$7*'2_Couts_evites'!$C$7/12*G28 | H30: ='2_Couts_evites'!$B$7*'2_Couts_evites'!$C$7/12*H28 | I30: ='2_Couts_evites'!$B$7*'2_Couts_evites'!$C$7/12*I28 | J30: ='2_Couts_evites'!$B$7*'2_Couts_evites'!$C$7/12*J28 | ... Z30: ='2_Couts_evites'!$B$7*'2_Couts_evites'!$C$7/12*Z28
A31: Exploitation interne (0,25 ETP) | B31: =SUM(C31:Z31) | C31: ='2_Couts_evites'!$B$8*'2_Couts_evites'!$C$8/12*C28 | D31: ='2_Couts_evites'!$B$8*'2_Couts_evites'!$C$8/12*D28 | E31: ='2_Couts_evites'!$B$8*'2_Couts_evites'!$C$8/12*E28 | F31: ='2_Couts_evites'!$B$8*'2_Couts_evites'!$C$8/12*F28 | G31: ='2_Couts_evites'!$B$8*'2_Couts_evites'!$C$8/12*G28 | H31: ='2_Couts_evites'!$B$8*'2_Couts_evites'!$C$8/12*H28 | I31: ='2_Couts_evites'!$B$8*'2_Couts_evites'!$C$8/12*I28 | J31: ='2_Couts_evites'!$B$8*'2_Couts_evites'!$C$8/12*J28 | ... Z31: ='2_Couts_evites'!$B$8*'2_Couts_evites'!$C$8/12*Z28
A32: Support N1/N2 : abus, réclamations, signalements | B32: =SUM(C32:Z32) | C32: ='2_Couts_evites'!$B$9*'2_Couts_evites'!$C$9/12*C28 | D32: ='2_Couts_evites'!$B$9*'2_Couts_evites'!$C$9/12*D28 | E32: ='2_Couts_evites'!$B$9*'2_Couts_evites'!$C$9/12*E28 | F32: ='2_Couts_evites'!$B$9*'2_Couts_evites'!$C$9/12*F28 | G32: ='2_Couts_evites'!$B$9*'2_Couts_evites'!$C$9/12*G28 | H32: ='2_Couts_evites'!$B$9*'2_Couts_evites'!$C$9/12*H28 | I32: ='2_Couts_evites'!$B$9*'2_Couts_evites'!$C$9/12*I28 | J32: ='2_Couts_evites'!$B$9*'2_Couts_evites'!$C$9/12*J28 | ... Z32: ='2_Couts_evites'!$B$9*'2_Couts_evites'!$C$9/12*Z28
A33: Licences et composants propriétaires | B33: =SUM(C33:Z33) | C33: ='2_Couts_evites'!$B$10*'2_Couts_evites'!$C$10/12*C28 | D33: ='2_Couts_evites'!$B$10*'2_Couts_evites'!$C$10/12*D28 | E33: ='2_Couts_evites'!$B$10*'2_Couts_evites'!$C$10/12*E28 | F33: ='2_Couts_evites'!$B$10*'2_Couts_evites'!$C$10/12*F28 | G33: ='2_Couts_evites'!$B$10*'2_Couts_evites'!$C$10/12*G28 | H33: ='2_Couts_evites'!$B$10*'2_Couts_evites'!$C$10/12*H28 | I33: ='2_Couts_evites'!$B$10*'2_Couts_evites'!$C$10/12*I28 | J33: ='2_Couts_evites'!$B$10*'2_Couts_evites'!$C$10/12*J28 | ... Z33: ='2_Couts_evites'!$B$10*'2_Couts_evites'!$C$10/12*Z28
A34: Acheminement des SMS du service historique | B34: =SUM(C34:Z34) | C34: ='2_Couts_evites'!$B$11*'2_Couts_evites'!$C$11/12*C28 | D34: ='2_Couts_evites'!$B$11*'2_Couts_evites'!$C$11/12*D28 | E34: ='2_Couts_evites'!$B$11*'2_Couts_evites'!$C$11/12*E28 | F34: ='2_Couts_evites'!$B$11*'2_Couts_evites'!$C$11/12*F28 | G34: ='2_Couts_evites'!$B$11*'2_Couts_evites'!$C$11/12*G28 | H34: ='2_Couts_evites'!$B$11*'2_Couts_evites'!$C$11/12*H28 | I34: ='2_Couts_evites'!$B$11*'2_Couts_evites'!$C$11/12*I28 | J34: ='2_Couts_evites'!$B$11*'2_Couts_evites'!$C$11/12*J28 | ... Z34: ='2_Couts_evites'!$B$11*'2_Couts_evites'!$C$11/12*Z28
A35: TOTAL COUTS EVITES | B35: =SUM(C35:Z35) | C35: =SUM(C29:C34) | D35: =SUM(D29:D34) | E35: =SUM(E29:E34) | F35: =SUM(F29:F34) | G35: =SUM(G29:G34) | H35: =SUM(H29:H34) | I35: =SUM(I29:I34) | J35: =SUM(J29:J34) | ... Z35: =SUM(Z29:Z34)
A36: COUTS FIXES DU SERVICE NOUVELLE GENERATION
A37: Run technique et produit (à compter de la bascule) | B37: =SUM(C37:Z37) | C37: =IF(1>='1_Hypotheses'!$C$48,-'1_Hypotheses'!$C$36*'1_Hypotheses'!$C$37/12,0) | D37: =IF(2>='1_Hypotheses'!$C$48,-'1_Hypotheses'!$C$36*'1_Hypotheses'!$C$37/12,0) | E37: =IF(3>='1_Hypotheses'!$C$48,-'1_Hypotheses'!$C$36*'1_Hypotheses'!$C$37/12,0) | F37: =IF(4>='1_Hypotheses'!$C$48,-'1_Hypotheses'!$C$36*'1_Hypotheses'!$C$37/12,0) | G37: =IF(5>='1_Hypotheses'!$C$48,-'1_Hypotheses'!$C$36*'1_Hypotheses'!$C$37/12,0) | H37: =IF(6>='1_Hypotheses'!$C$48,-'1_Hypotheses'!$C$36*'1_Hypotheses'!$C$37/12,0) | I37: =IF(7>='1_Hypotheses'!$C$48,-'1_Hypotheses'!$C$36*'1_Hypotheses'!$C$37/12,0) | J37: =IF(8>='1_Hypotheses'!$C$48,-'1_Hypotheses'!$C$36*'1_Hypotheses'!$C$37/12,0) | K37: =IF(9>='1_Hypotheses'!$C$48,-'1_Hypotheses'!$C$36*'1_Hypotheses'!$C$37/12,0) | L37: =IF(10>='1_Hypotheses'!$C$48,-'1_Hypotheses'!$C$36*'1_Hypotheses'!$C$37/12,0) | M37: =IF(11>='1_Hypotheses'!$C$48,-'1_Hypotheses'!$C$36*'1_Hypotheses'!$C$37/12,0) | N37: =IF(12>='1_Hypotheses'!$C$48,-'1_Hypotheses'!$C$36*'1_Hypotheses'!$C$37/12,0) | O37: =IF(13>='1_Hypotheses'!$C$48,-'1_Hypotheses'!$C$36*'1_Hypotheses'!$C$37/12,0) | P37: =IF(14>='1_Hypotheses'!$C$48,-'1_Hypotheses'!$C$36*'1_Hypotheses'!$C$37/12,0) | Q37: =IF(15>='1_Hypotheses'!$C$48,-'1_Hypotheses'!$C$36*'1_Hypotheses'!$C$37/12,0) | R37: =IF(16>='1_Hypotheses'!$C$48,-'1_Hypotheses'!$C$36*'1_Hypotheses'!$C$37/12,0) | S37: =IF(17>='1_Hypotheses'!$C$48,-'1_Hypotheses'!$C$36*'1_Hypotheses'!$C$37/12,0) | T37: =IF(18>='1_Hypotheses'!$C$48,-'1_Hypotheses'!$C$36*'1_Hypotheses'!$C$37/12,0) | U37: =IF(19>='1_Hypotheses'!$C$48,-'1_Hypotheses'!$C$36*'1_Hypotheses'!$C$37/12,0) | V37: =IF(20>='1_Hypotheses'!$C$48,-'1_Hypotheses'!$C$36*'1_Hypotheses'!$C$37/12,0) | W37: =IF(21>='1_Hypotheses'!$C$48,-'1_Hypotheses'!$C$36*'1_Hypotheses'!$C$37/12,0) | X37: =IF(22>='1_Hypotheses'!$C$48,-'1_Hypotheses'!$C$36*'1_Hypotheses'!$C$37/12,0) | Y37: =IF(23>='1_Hypotheses'!$C$48,-'1_Hypotheses'!$C$36*'1_Hypotheses'!$C$37/12,0) | Z37: =IF(24>='1_Hypotheses'!$C$48,-'1_Hypotheses'!$C$36*'1_Hypotheses'!$C$37/12,0)
A38: Hébergement (production après bascule, environnements avant) | B38: =SUM(C38:Z38) | C38: =IF(1>='1_Hypotheses'!$C$48,-'1_Hypotheses'!$C$38,-'1_Hypotheses'!$C$41) | D38: =IF(2>='1_Hypotheses'!$C$48,-'1_Hypotheses'!$C$38,-'1_Hypotheses'!$C$41) | E38: =IF(3>='1_Hypotheses'!$C$48,-'1_Hypotheses'!$C$38,-'1_Hypotheses'!$C$41) | F38: =IF(4>='1_Hypotheses'!$C$48,-'1_Hypotheses'!$C$38,-'1_Hypotheses'!$C$41) | G38: =IF(5>='1_Hypotheses'!$C$48,-'1_Hypotheses'!$C$38,-'1_Hypotheses'!$C$41) | H38: =IF(6>='1_Hypotheses'!$C$48,-'1_Hypotheses'!$C$38,-'1_Hypotheses'!$C$41) | I38: =IF(7>='1_Hypotheses'!$C$48,-'1_Hypotheses'!$C$38,-'1_Hypotheses'!$C$41) | J38: =IF(8>='1_Hypotheses'!$C$48,-'1_Hypotheses'!$C$38,-'1_Hypotheses'!$C$41) | K38: =IF(9>='1_Hypotheses'!$C$48,-'1_Hypotheses'!$C$38,-'1_Hypotheses'!$C$41) | L38: =IF(10>='1_Hypotheses'!$C$48,-'1_Hypotheses'!$C$38,-'1_Hypotheses'!$C$41) | M38: =IF(11>='1_Hypotheses'!$C$48,-'1_Hypotheses'!$C$38,-'1_Hypotheses'!$C$41) | N38: =IF(12>='1_Hypotheses'!$C$48,-'1_Hypotheses'!$C$38,-'1_Hypotheses'!$C$41) | O38: =IF(13>='1_Hypotheses'!$C$48,-'1_Hypotheses'!$C$38,-'1_Hypotheses'!$C$41) | P38: =IF(14>='1_Hypotheses'!$C$48,-'1_Hypotheses'!$C$38,-'1_Hypotheses'!$C$41) | Q38: =IF(15>='1_Hypotheses'!$C$48,-'1_Hypotheses'!$C$38,-'1_Hypotheses'!$C$41) | R38: =IF(16>='1_Hypotheses'!$C$48,-'1_Hypotheses'!$C$38,-'1_Hypotheses'!$C$41) | S38: =IF(17>='1_Hypotheses'!$C$48,-'1_Hypotheses'!$C$38,-'1_Hypotheses'!$C$41) | T38: =IF(18>='1_Hypotheses'!$C$48,-'1_Hypotheses'!$C$38,-'1_Hypotheses'!$C$41) | U38: =IF(19>='1_Hypotheses'!$C$48,-'1_Hypotheses'!$C$38,-'1_Hypotheses'!$C$41) | V38: =IF(20>='1_Hypotheses'!$C$48,-'1_Hypotheses'!$C$38,-'1_Hypotheses'!$C$41) | W38: =IF(21>='1_Hypotheses'!$C$48,-'1_Hypotheses'!$C$38,-'1_Hypotheses'!$C$41) | X38: =IF(22>='1_Hypotheses'!$C$48,-'1_Hypotheses'!$C$38,-'1_Hypotheses'!$C$41) | Y38: =IF(23>='1_Hypotheses'!$C$48,-'1_Hypotheses'!$C$38,-'1_Hypotheses'!$C$41) | Z38: =IF(24>='1_Hypotheses'!$C$48,-'1_Hypotheses'!$C$38,-'1_Hypotheses'!$C$41)
A39: Support et modération | B39: =SUM(C39:Z39) | C39: =IF(1>='1_Hypotheses'!$C$48,-'1_Hypotheses'!$C$39,0) | D39: =IF(2>='1_Hypotheses'!$C$48,-'1_Hypotheses'!$C$39,0) | E39: =IF(3>='1_Hypotheses'!$C$48,-'1_Hypotheses'!$C$39,0) | F39: =IF(4>='1_Hypotheses'!$C$48,-'1_Hypotheses'!$C$39,0) | G39: =IF(5>='1_Hypotheses'!$C$48,-'1_Hypotheses'!$C$39,0) | H39: =IF(6>='1_Hypotheses'!$C$48,-'1_Hypotheses'!$C$39,0) | I39: =IF(7>='1_Hypotheses'!$C$48,-'1_Hypotheses'!$C$39,0) | J39: =IF(8>='1_Hypotheses'!$C$48,-'1_Hypotheses'!$C$39,0) | K39: =IF(9>='1_Hypotheses'!$C$48,-'1_Hypotheses'!$C$39,0) | L39: =IF(10>='1_Hypotheses'!$C$48,-'1_Hypotheses'!$C$39,0) | M39: =IF(11>='1_Hypotheses'!$C$48,-'1_Hypotheses'!$C$39,0) | N39: =IF(12>='1_Hypotheses'!$C$48,-'1_Hypotheses'!$C$39,0) | O39: =IF(13>='1_Hypotheses'!$C$48,-'1_Hypotheses'!$C$39,0) | P39: =IF(14>='1_Hypotheses'!$C$48,-'1_Hypotheses'!$C$39,0) | Q39: =IF(15>='1_Hypotheses'!$C$48,-'1_Hypotheses'!$C$39,0) | R39: =IF(16>='1_Hypotheses'!$C$48,-'1_Hypotheses'!$C$39,0) | S39: =IF(17>='1_Hypotheses'!$C$48,-'1_Hypotheses'!$C$39,0) | T39: =IF(18>='1_Hypotheses'!$C$48,-'1_Hypotheses'!$C$39,0) | U39: =IF(19>='1_Hypotheses'!$C$48,-'1_Hypotheses'!$C$39,0) | V39: =IF(20>='1_Hypotheses'!$C$48,-'1_Hypotheses'!$C$39,0) | W39: =IF(21>='1_Hypotheses'!$C$48,-'1_Hypotheses'!$C$39,0) | X39: =IF(22>='1_Hypotheses'!$C$48,-'1_Hypotheses'!$C$39,0) | Y39: =IF(23>='1_Hypotheses'!$C$48,-'1_Hypotheses'!$C$39,0) | Z39: =IF(24>='1_Hypotheses'!$C$48,-'1_Hypotheses'!$C$39,0)
A40: Communication et notoriété | B40: =SUM(C40:Z40) | C40: =IF(1>='1_Hypotheses'!$C$48,-'1_Hypotheses'!$C$40,0) | D40: =IF(2>='1_Hypotheses'!$C$48,-'1_Hypotheses'!$C$40,0) | E40: =IF(3>='1_Hypotheses'!$C$48,-'1_Hypotheses'!$C$40,0) | F40: =IF(4>='1_Hypotheses'!$C$48,-'1_Hypotheses'!$C$40,0) | G40: =IF(5>='1_Hypotheses'!$C$48,-'1_Hypotheses'!$C$40,0) | H40: =IF(6>='1_Hypotheses'!$C$48,-'1_Hypotheses'!$C$40,0) | I40: =IF(7>='1_Hypotheses'!$C$48,-'1_Hypotheses'!$C$40,0) | J40: =IF(8>='1_Hypotheses'!$C$48,-'1_Hypotheses'!$C$40,0) | K40: =IF(9>='1_Hypotheses'!$C$48,-'1_Hypotheses'!$C$40,0) | L40: =IF(10>='1_Hypotheses'!$C$48,-'1_Hypotheses'!$C$40,0) | M40: =IF(11>='1_Hypotheses'!$C$48,-'1_Hypotheses'!$C$40,0) | N40: =IF(12>='1_Hypotheses'!$C$48,-'1_Hypotheses'!$C$40,0) | O40: =IF(13>='1_Hypotheses'!$C$48,-'1_Hypotheses'!$C$40,0) | P40: =IF(14>='1_Hypotheses'!$C$48,-'1_Hypotheses'!$C$40,0) | Q40: =IF(15>='1_Hypotheses'!$C$48,-'1_Hypotheses'!$C$40,0) | R40: =IF(16>='1_Hypotheses'!$C$48,-'1_Hypotheses'!$C$40,0) | S40: =IF(17>='1_Hypotheses'!$C$48,-'1_Hypotheses'!$C$40,0) | T40: =IF(18>='1_Hypotheses'!$C$48,-'1_Hypotheses'!$C$40,0) | U40: =IF(19>='1_Hypotheses'!$C$48,-'1_Hypotheses'!$C$40,0) | V40: =IF(20>='1_Hypotheses'!$C$48,-'1_Hypotheses'!$C$40,0) | W40: =IF(21>='1_Hypotheses'!$C$48,-'1_Hypotheses'!$C$40,0) | X40: =IF(22>='1_Hypotheses'!$C$48,-'1_Hypotheses'!$C$40,0) | Y40: =IF(23>='1_Hypotheses'!$C$48,-'1_Hypotheses'!$C$40,0) | Z40: =IF(24>='1_Hypotheses'!$C$48,-'1_Hypotheses'!$C$40,0)
A41: TOTAL COUTS FIXES | B41: =SUM(C41:Z41) | C41: =SUM(C37:C40) | D41: =SUM(D37:D40) | E41: =SUM(E37:E40) | F41: =SUM(F37:F40) | G41: =SUM(G37:G40) | H41: =SUM(H37:H40) | I41: =SUM(I37:I40) | J41: =SUM(J37:J40) | ... Z41: =SUM(Z37:Z40)
...

Sheet 5_PL_Central
A1: COMPTE DE RESULTAT MENSUEL 24 MOIS - SCENARIO CENTRAL
A2: Montants en XPF HT. Vue service Mobitag Nouvelle Génération (périmètre OPT-NC).
A3: Aucune ligne de revenu issue de la vente de volume SMS au particulier.
A5: Poste | B5: Total 24M | C5: M1 | D5: M2 | E5: M3 | F5: M4 | G5: M5 | H5: M6 | I5: M7 | J5: M8 | K5: M9 | L5: M10 | M5: M11 | N5: M12 | O5: M13 | P5: M14 | Q5: M15 | R5: M16 | S5: M17 | T5: M18 | U5: M19 | V5: M20 | W5: M21 | X5: M22 | Y5: M23 | Z5: M24
A6: VOLUMETRIE
A7: Utilisateurs actifs mensuels (MAU) | B7: =Z7 | C7: ='1_Hypotheses'!$D$7 | D7: =MIN('1_Hypotheses'!$D$9,C7*(1+'1_Hypotheses'!$D$8)) | E7: =MIN('1_Hypotheses'!$D$9,D7*(1+'1_Hypotheses'!$D$8)) | F7: =MIN('1_Hypotheses'!$D$9,E7*(1+'1_Hypotheses'!$D$8)) | G7: =MIN('1_Hypotheses'!$D$9,F7*(1+'1_Hypotheses'!$D$8)) | H7: =MIN('1_Hypotheses'!$D$9,G7*(1+'1_Hypotheses'!$D$8)) | I7: =MIN('1_Hypotheses'!$D$9,H7*(1+'1_Hypotheses'!$D$8)) | J7: =MIN('1_Hypotheses'!$D$9,I7*(1+'1_Hypotheses'!$D$8)) | K7: =MIN('1_Hypotheses'!$D$9,J7*(1+'1_Hypotheses'!$D$8)) | ... Z7: =MIN('1_Hypotheses'!$D$9,Y7*(1+'1_Hypotheses'!$D$8))
A8: SMS gratuits envoyés | B8: =SUM(C8:Z8) | C8: =C7*'1_Hypotheses'!$D$10 | D8: =D7*'1_Hypotheses'!$D$10 | E8: =E7*'1_Hypotheses'!$D$10 | F8: =F7*'1_Hypotheses'!$D$10 | G8: =G7*'1_Hypotheses'!$D$10 | H8: =H7*'1_Hypotheses'!$D$10 | I8: =I7*'1_Hypotheses'!$D$10 | J8: =J7*'1_Hypotheses'!$D$10 | ... Z8: =Z7*'1_Hypotheses'!$D$10
A9: Usages professionnels détectés | B9: =SUM(C9:Z9) | C9: =C7*'1_Hypotheses'!$D$12 | D9: =D7*'1_Hypotheses'!$D$12 | E9: =E7*'1_Hypotheses'!$D$12 | F9: =F7*'1_Hypotheses'!$D$12 | G9: =G7*'1_Hypotheses'!$D$12 | H9: =H7*'1_Hypotheses'!$D$12 | I9: =I7*'1_Hypotheses'!$D$12 | J9: =J7*'1_Hypotheses'!$D$12 | ... Z9: =Z7*'1_Hypotheses'!$D$12
A10: Utilisateurs sans ligne active détectés | B10: =SUM(C10:Z10) | C10: =C7*'1_Hypotheses'!$D$20 | D10: =D7*'1_Hypotheses'!$D$20 | E10: =E7*'1_Hypotheses'!$D$20 | F10: =F7*'1_Hypotheses'!$D$20 | G10: =G7*'1_Hypotheses'!$D$20 | H10: =H7*'1_Hypotheses'!$D$20 | I10: =I7*'1_Hypotheses'!$D$20 | J10: =J7*'1_Hypotheses'!$D$20 | ... Z10: =Z7*'1_Hypotheses'!$D$20
A11: APPORTS D'AFFAIRES - CONSTITUTION DES STOCKS
A12: Nouveaux clients Helia PRO apportés | B12: =SUM(C12:Z12) | C12: =IF(1>='1_Hypotheses'!$D$18,C9*'1_Hypotheses'!$D$13*'1_Hypotheses'!$D$14,0) | D12: =IF(2>='1_Hypotheses'!$D$18,D9*'1_Hypotheses'!$D$13*'1_Hypotheses'!$D$14,0) | E12: =IF(3>='1_Hypotheses'!$D$18,E9*'1_Hypotheses'!$D$13*'1_Hypotheses'!$D$14,0) | F12: =IF(4>='1_Hypotheses'!$D$18,F9*'1_Hypotheses'!$D$13*'1_Hypotheses'!$D$14,0) | G12: =IF(5>='1_Hypotheses'!$D$18,G9*'1_Hypotheses'!$D$13*'1_Hypotheses'!$D$14,0) | H12: =IF(6>='1_Hypotheses'!$D$18,H9*'1_Hypotheses'!$D$13*'1_Hypotheses'!$D$14,0) | I12: =IF(7>='1_Hypotheses'!$D$18,I9*'1_Hypotheses'!$D$13*'1_Hypotheses'!$D$14,0) | J12: =IF(8>='1_Hypotheses'!$D$18,J9*'1_Hypotheses'!$D$13*'1_Hypotheses'!$D$14,0) | K12: =IF(9>='1_Hypotheses'!$D$18,K9*'1_Hypotheses'!$D$13*'1_Hypotheses'!$D$14,0) | L12: =IF(10>='1_Hypotheses'!$D$18,L9*'1_Hypotheses'!$D$13*'1_Hypotheses'!$D$14,0) | M12: =IF(11>='1_Hypotheses'!$D$18,M9*'1_Hypotheses'!$D$13*'1_Hypotheses'!$D$14,0) | N12: =IF(12>='1_Hypotheses'!$D$18,N9*'1_Hypotheses'!$D$13*'1_Hypotheses'!$D$14,0) | O12: =IF(13>='1_Hypotheses'!$D$18,O9*'1_Hypotheses'!$D$13*'1_Hypotheses'!$D$14,0) | P12: =IF(14>='1_Hypotheses'!$D$18,P9*'1_Hypotheses'!$D$13*'1_Hypotheses'!$D$14,0) | Q12: =IF(15>='1_Hypotheses'!$D$18,Q9*'1_Hypotheses'!$D$13*'1_Hypotheses'!$D$14,0) | R12: =IF(16>='1_Hypotheses'!$D$18,R9*'1_Hypotheses'!$D$13*'1_Hypotheses'!$D$14,0) | S12: =IF(17>='1_Hypotheses'!$D$18,S9*'1_Hypotheses'!$D$13*'1_Hypotheses'!$D$14,0) | T12: =IF(18>='1_Hypotheses'!$D$18,T9*'1_Hypotheses'!$D$13*'1_Hypotheses'!$D$14,0) | U12: =IF(19>='1_Hypotheses'!$D$18,U9*'1_Hypotheses'!$D$13*'1_Hypotheses'!$D$14,0) | V12: =IF(20>='1_Hypotheses'!$D$18,V9*'1_Hypotheses'!$D$13*'1_Hypotheses'!$D$14,0) | W12: =IF(21>='1_Hypotheses'!$D$18,W9*'1_Hypotheses'!$D$13*'1_Hypotheses'!$D$14,0) | X12: =IF(22>='1_Hypotheses'!$D$18,X9*'1_Hypotheses'!$D$13*'1_Hypotheses'!$D$14,0) | Y12: =IF(23>='1_Hypotheses'!$D$18,Y9*'1_Hypotheses'!$D$13*'1_Hypotheses'!$D$14,0) | Z12: =IF(24>='1_Hypotheses'!$D$18,Z9*'1_Hypotheses'!$D$13*'1_Hypotheses'!$D$14,0)
A13: Stock de clients Helia PRO apportés | B13: =Z13 | C13: =C12 | D13: =C13*(1-'1_Hypotheses'!$D$17)+D12 | E13: =D13*(1-'1_Hypotheses'!$D$17)+E12 | F13: =E13*(1-'1_Hypotheses'!$D$17)+F12 | G13: =F13*(1-'1_Hypotheses'!$D$17)+G12 | H13: =G13*(1-'1_Hypotheses'!$D$17)+H12 | I13: =H13*(1-'1_Hypotheses'!$D$17)+I12 | J13: =I13*(1-'1_Hypotheses'!$D$17)+J12 | K13: =J13*(1-'1_Hypotheses'!$D$17)+K12 | ... Z13: =Y13*(1-'1_Hypotheses'!$D$17)+Z12
A14: Nouvelles lignes grand public activées | B14: =SUM(C14:Z14) | C14: =IF(1>='1_Hypotheses'!$D$26,C10*'1_Hypotheses'!$D$21*'1_Hypotheses'!$D$22,0) | D14: =IF(2>='1_Hypotheses'!$D$26,D10*'1_Hypotheses'!$D$21*'1_Hypotheses'!$D$22,0) | E14: =IF(3>='1_Hypotheses'!$D$26,E10*'1_Hypotheses'!$D$21*'1_Hypotheses'!$D$22,0) | F14: =IF(4>='1_Hypotheses'!$D$26,F10*'1_Hypotheses'!$D$21*'1_Hypotheses'!$D$22,0) | G14: =IF(5>='1_Hypotheses'!$D$26,G10*'1_Hypotheses'!$D$21*'1_Hypotheses'!$D$22,0) | H14: =IF(6>='1_Hypotheses'!$D$26,H10*'1_Hypotheses'!$D$21*'1_Hypotheses'!$D$22,0) | I14: =IF(7>='1_Hypotheses'!$D$26,I10*'1_Hypotheses'!$D$21*'1_Hypotheses'!$D$22,0) | J14: =IF(8>='1_Hypotheses'!$D$26,J10*'1_Hypotheses'!$D$21*'1_Hypotheses'!$D$22,0) | K14: =IF(9>='1_Hypotheses'!$D$26,K10*'1_Hypotheses'!$D$21*'1_Hypotheses'!$D$22,0) | L14: =IF(10>='1_Hypotheses'!$D$26,L10*'1_Hypotheses'!$D$21*'1_Hypotheses'!$D$22,0) | M14: =IF(11>='1_Hypotheses'!$D$26,M10*'1_Hypotheses'!$D$21*'1_Hypotheses'!$D$22,0) | N14: =IF(12>='1_Hypotheses'!$D$26,N10*'1_Hypotheses'!$D$21*'1_Hypotheses'!$D$22,0) | O14: =IF(13>='1_Hypotheses'!$D$26,O10*'1_Hypotheses'!$D$21*'1_Hypotheses'!$D$22,0) | P14: =IF(14>='1_Hypotheses'!$D$26,P10*'1_Hypotheses'!$D$21*'1_Hypotheses'!$D$22,0) | Q14: =IF(15>='1_Hypotheses'!$D$26,Q10*'1_Hypotheses'!$D$21*'1_Hypotheses'!$D$22,0) | R14: =IF(16>='1_Hypotheses'!$D$26,R10*'1_Hypotheses'!$D$21*'1_Hypotheses'!$D$22,0) | S14: =IF(17>='1_Hypotheses'!$D$26,S10*'1_Hypotheses'!$D$21*'1_Hypotheses'!$D$22,0) | T14: =IF(18>='1_Hypotheses'!$D$26,T10*'1_Hypotheses'!$D$21*'1_Hypotheses'!$D$22,0) | U14: =IF(19>='1_Hypotheses'!$D$26,U10*'1_Hypotheses'!$D$21*'1_Hypotheses'!$D$22,0) | V14: =IF(20>='1_Hypotheses'!$D$26,V10*'1_Hypotheses'!$D$21*'1_Hypotheses'!$D$22,0) | W14: =IF(21>='1_Hypotheses'!$D$26,W10*'1_Hypotheses'!$D$21*'1_Hypotheses'!$D$22,0) | X14: =IF(22>='1_Hypotheses'!$D$26,X10*'1_Hypotheses'!$D$21*'1_Hypotheses'!$D$22,0) | Y14: =IF(23>='1_Hypotheses'!$D$26,Y10*'1_Hypotheses'!$D$21*'1_Hypotheses'!$D$22,0) | Z14: =IF(24>='1_Hypotheses'!$D$26,Z10*'1_Hypotheses'!$D$21*'1_Hypotheses'!$D$22,0)
A15: Stock de lignes grand public apportées | B15: =Z15 | C15: =C14 | D15: =C15*(1-'1_Hypotheses'!$D$25)+D14 | E15: =D15*(1-'1_Hypotheses'!$D$25)+E14 | F15: =E15*(1-'1_Hypotheses'!$D$25)+F14 | G15: =F15*(1-'1_Hypotheses'!$D$25)+G14 | H15: =G15*(1-'1_Hypotheses'!$D$25)+H14 | I15: =H15*(1-'1_Hypotheses'!$D$25)+I14 | J15: =I15*(1-'1_Hypotheses'!$D$25)+J14 | K15: =J15*(1-'1_Hypotheses'!$D$25)+K14 | ... Z15: =Y15*(1-'1_Hypotheses'!$D$25)+Z14
A16: CHIFFRE D'AFFAIRES / VALEUR CREEE
A17: Apport d'affaires B2B - Helia PRO | B17: =SUM(C17:Z17) | C17: =C13*'1_Hypotheses'!$D$15/12*'1_Hypotheses'!$D$16 | D17: =D13*'1_Hypotheses'!$D$15/12*'1_Hypotheses'!$D$16 | E17: =E13*'1_Hypotheses'!$D$15/12*'1_Hypotheses'!$D$16 | F17: =F13*'1_Hypotheses'!$D$15/12*'1_Hypotheses'!$D$16 | G17: =G13*'1_Hypotheses'!$D$15/12*'1_Hypotheses'!$D$16 | H17: =H13*'1_Hypotheses'!$D$15/12*'1_Hypotheses'!$D$16 | I17: =I13*'1_Hypotheses'!$D$15/12*'1_Hypotheses'!$D$16 | J17: =J13*'1_Hypotheses'!$D$15/12*'1_Hypotheses'!$D$16 | ... Z17: =Z13*'1_Hypotheses'!$D$15/12*'1_Hypotheses'!$D$16
A18: Apport d'affaires B2C - activation de lignes | B18: =SUM(C18:Z18) | C18: =C15*'1_Hypotheses'!$D$23/12*'1_Hypotheses'!$D$24 | D18: =D15*'1_Hypotheses'!$D$23/12*'1_Hypotheses'!$D$24 | E18: =E15*'1_Hypotheses'!$D$23/12*'1_Hypotheses'!$D$24 | F18: =F15*'1_Hypotheses'!$D$23/12*'1_Hypotheses'!$D$24 | G18: =G15*'1_Hypotheses'!$D$23/12*'1_Hypotheses'!$D$24 | H18: =H15*'1_Hypotheses'!$D$23/12*'1_Hypotheses'!$D$24 | I18: =I15*'1_Hypotheses'!$D$23/12*'1_Hypotheses'!$D$24 | J18: =J15*'1_Hypotheses'!$D$23/12*'1_Hypotheses'!$D$24 | ... Z18: =Z15*'1_Hypotheses'!$D$23/12*'1_Hypotheses'!$D$24
A19: Sponsoring consenti | B19: =SUM(C19:Z19) | C19: =IF(1<'1_Hypotheses'!$D$29,0,'1_Hypotheses'!$D$28*MIN(1,(1-'1_Hypotheses'!$D$29+1)/'1_Hypotheses'!$D$30)) | D19: =IF(2<'1_Hypotheses'!$D$29,0,'1_Hypotheses'!$D$28*MIN(1,(2-'1_Hypotheses'!$D$29+1)/'1_Hypotheses'!$D$30)) | E19: =IF(3<'1_Hypotheses'!$D$29,0,'1_Hypotheses'!$D$28*MIN(1,(3-'1_Hypotheses'!$D$29+1)/'1_Hypotheses'!$D$30)) | F19: =IF(4<'1_Hypotheses'!$D$29,0,'1_Hypotheses'!$D$28*MIN(1,(4-'1_Hypotheses'!$D$29+1)/'1_Hypotheses'!$D$30)) | G19: =IF(5<'1_Hypotheses'!$D$29,0,'1_Hypotheses'!$D$28*MIN(1,(5-'1_Hypotheses'!$D$29+1)/'1_Hypotheses'!$D$30)) | H19: =IF(6<'1_Hypotheses'!$D$29,0,'1_Hypotheses'!$D$28*MIN(1,(6-'1_Hypotheses'!$D$29+1)/'1_Hypotheses'!$D$30)) | I19: =IF(7<'1_Hypotheses'!$D$29,0,'1_Hypotheses'!$D$28*MIN(1,(7-'1_Hypotheses'!$D$29+1)/'1_Hypotheses'!$D$30)) | J19: =IF(8<'1_Hypotheses'!$D$29,0,'1_Hypotheses'!$D$28*MIN(1,(8-'1_Hypotheses'!$D$29+1)/'1_Hypotheses'!$D$30)) | K19: =IF(9<'1_Hypotheses'!$D$29,0,'1_Hypotheses'!$D$28*MIN(1,(9-'1_Hypotheses'!$D$29+1)/'1_Hypotheses'!$D$30)) | L19: =IF(10<'1_Hypotheses'!$D$29,0,'1_Hypotheses'!$D$28*MIN(1,(10-'1_Hypotheses'!$D$29+1)/'1_Hypotheses'!$D$30)) | M19: =IF(11<'1_Hypotheses'!$D$29,0,'1_Hypotheses'!$D$28*MIN(1,(11-'1_Hypotheses'!$D$29+1)/'1_Hypotheses'!$D$30)) | N19: =IF(12<'1_Hypotheses'!$D$29,0,'1_Hypotheses'!$D$28*MIN(1,(12-'1_Hypotheses'!$D$29+1)/'1_Hypotheses'!$D$30)) | O19: =IF(13<'1_Hypotheses'!$D$29,0,'1_Hypotheses'!$D$28*MIN(1,(13-'1_Hypotheses'!$D$29+1)/'1_Hypotheses'!$D$30)) | P19: =IF(14<'1_Hypotheses'!$D$29,0,'1_Hypotheses'!$D$28*MIN(1,(14-'1_Hypotheses'!$D$29+1)/'1_Hypotheses'!$D$30)) | Q19: =IF(15<'1_Hypotheses'!$D$29,0,'1_Hypotheses'!$D$28*MIN(1,(15-'1_Hypotheses'!$D$29+1)/'1_Hypotheses'!$D$30)) | R19: =IF(16<'1_Hypotheses'!$D$29,0,'1_Hypotheses'!$D$28*MIN(1,(16-'1_Hypotheses'!$D$29+1)/'1_Hypotheses'!$D$30)) | S19: =IF(17<'1_Hypotheses'!$D$29,0,'1_Hypotheses'!$D$28*MIN(1,(17-'1_Hypotheses'!$D$29+1)/'1_Hypotheses'!$D$30)) | T19: =IF(18<'1_Hypotheses'!$D$29,0,'1_Hypotheses'!$D$28*MIN(1,(18-'1_Hypotheses'!$D$29+1)/'1_Hypotheses'!$D$30)) | U19: =IF(19<'1_Hypotheses'!$D$29,0,'1_Hypotheses'!$D$28*MIN(1,(19-'1_Hypotheses'!$D$29+1)/'1_Hypotheses'!$D$30)) | V19: =IF(20<'1_Hypotheses'!$D$29,0,'1_Hypotheses'!$D$28*MIN(1,(20-'1_Hypotheses'!$D$29+1)/'1_Hypotheses'!$D$30)) | W19: =IF(21<'1_Hypotheses'!$D$29,0,'1_Hypotheses'!$D$28*MIN(1,(21-'1_Hypotheses'!$D$29+1)/'1_Hypotheses'!$D$30)) | X19: =IF(22<'1_Hypotheses'!$D$29,0,'1_Hypotheses'!$D$28*MIN(1,(22-'1_Hypotheses'!$D$29+1)/'1_Hypotheses'!$D$30)) | Y19: =IF(23<'1_Hypotheses'!$D$29,0,'1_Hypotheses'!$D$28*MIN(1,(23-'1_Hypotheses'!$D$29+1)/'1_Hypotheses'!$D$30)) | Z19: =IF(24<'1_Hypotheses'!$D$29,0,'1_Hypotheses'!$D$28*MIN(1,(24-'1_Hypotheses'!$D$29+1)/'1_Hypotheses'!$D$30))
A20: CHIFFRE D'AFFAIRES TOTAL | B20: =SUM(C20:Z20) | C20: =SUM(C17:C19) | D20: =SUM(D17:D19) | E20: =SUM(E17:E19) | F20: =SUM(F17:F19) | G20: =SUM(G17:G19) | H20: =SUM(H17:H19) | I20: =SUM(I17:I19) | J20: =SUM(J17:J19) | ... Z20: =SUM(Z17:Z19)
A21: COUTS VARIABLES ET REVERSEMENTS
A22: Acheminement des SMS gratuits | B22: =SUM(C22:Z22) | C22: =-C8*'1_Hypotheses'!$D$33 | D22: =-D8*'1_Hypotheses'!$D$33 | E22: =-E8*'1_Hypotheses'!$D$33 | F22: =-F8*'1_Hypotheses'!$D$33 | G22: =-G8*'1_Hypotheses'!$D$33 | H22: =-H8*'1_Hypotheses'!$D$33 | I22: =-I8*'1_Hypotheses'!$D$33 | J22: =-J8*'1_Hypotheses'!$D$33 | ... Z22: =-Z8*'1_Hypotheses'!$D$33
A23: Infrastructure variable | B23: =SUM(C23:Z23) | C23: =-C7*'1_Hypotheses'!$D$34 | D23: =-D7*'1_Hypotheses'!$D$34 | E23: =-E7*'1_Hypotheses'!$D$34 | F23: =-F7*'1_Hypotheses'!$D$34 | G23: =-G7*'1_Hypotheses'!$D$34 | H23: =-H7*'1_Hypotheses'!$D$34 | I23: =-I7*'1_Hypotheses'!$D$34 | J23: =-J7*'1_Hypotheses'!$D$34 | ... Z23: =-Z7*'1_Hypotheses'!$D$34
A24: Reversement régie sponsoring | B24: =SUM(C24:Z24) | C24: =-C19*'1_Hypotheses'!$D$31 | D24: =-D19*'1_Hypotheses'!$D$31 | E24: =-E19*'1_Hypotheses'!$D$31 | F24: =-F19*'1_Hypotheses'!$D$31 | G24: =-G19*'1_Hypotheses'!$D$31 | H24: =-H19*'1_Hypotheses'!$D$31 | I24: =-I19*'1_Hypotheses'!$D$31 | J24: =-J19*'1_Hypotheses'!$D$31 | ... Z24: =-Z19*'1_Hypotheses'!$D$31
A25: TOTAL COUTS VARIABLES ET REVERSEMENTS | B25: =SUM(C25:Z25) | C25: =SUM(C22:C24) | D25: =SUM(D22:D24) | E25: =SUM(E22:E24) | F25: =SUM(F22:F24) | G25: =SUM(G22:G24) | H25: =SUM(H22:H24) | I25: =SUM(I22:I24) | J25: =SUM(J22:J24) | ... Z25: =SUM(Z22:Z24)
